 
New instance of bashtop version: 0.9.25 Pid: 1295033
 
New instance of bashtop version: 0.9.25 Pid: 1310282
 
New instance of bashtop version: 0.9.25 Pid: 1401896
 
New instance of bashtop version: 0.9.25 Pid: 1405393
 
New instance of bashtop version: 0.9.25 Pid: 1447939
 
New instance of bashtop version: 0.9.25 Pid: 1449330
 
New instance of bashtop version: 0.9.25 Pid: 1451007
 
New instance of bashtop version: 0.9.25 Pid: 1452774
 
New instance of bashtop version: 0.9.25 Pid: 1455914
 
New instance of bashtop version: 0.9.25 Pid: 1456783
 
New instance of bashtop version: 0.9.25 Pid: 1498022
Traceback (most recent call last):
  File "/usr/local/lib/python3.10/dist-packages/psutil/_common.py", line 441, in wrapper
    ret = self._cache[fun]
KeyError: <function Process.memory_info at 0x7fc553f83f40>

During handling of the above exception, another exception occurred:

Traceback (most recent call last):
  File "/tmp/mJa8DMg1iKBQ/bashtop.psutil", line 395, in <module>
    exec(command)
  File "<string>", line 1, in <module>
  File "/tmp/mJa8DMg1iKBQ/bashtop.psutil", line 224, in get_proc
    for p in sorted(psutil.process_iter(['pid', 'name', 'cmdline', 'num_threads', 'username', 'memory_percent', 'cpu_percent', 'cpu_times', 'create_time'], err), key=lambda p: eval(sort_cmd), reverse=reverse):
  File "/usr/local/lib/python3.10/dist-packages/psutil/__init__.py", line 1450, in process_iter
    proc.info = proc.as_dict(
  File "/usr/local/lib/python3.10/dist-packages/psutil/__init__.py", line 531, in as_dict
    ret = meth()
  File "/usr/local/lib/python3.10/dist-packages/psutil/__init__.py", line 1099, in memory_percent
    metrics = fun()
  File "/usr/local/lib/python3.10/dist-packages/psutil/_common.py", line 448, in wrapper
    ret = fun(self)
  File "/usr/local/lib/python3.10/dist-packages/psutil/__init__.py", line 1061, in memory_info
    return self._proc.memory_info()
  File "/usr/local/lib/python3.10/dist-packages/psutil/_pslinux.py", line 1661, in wrapper
    return fun(self, *args, **kwargs)
  File "/usr/local/lib/python3.10/dist-packages/psutil/_pslinux.py", line 1895, in memory_info
    with open_binary("%s/%s/statm" % (self._procfs_path, self.pid)) as f:
  File "/usr/local/lib/python3.10/dist-packages/psutil/_common.py", line 711, in open_binary
    return open(fname, "rb", **kwargs)
KeyboardInterrupt
/usr/bin/bashtop: line 4806: ${pycoproc[1]}: ambiguous redirect
 
New instance of bashtop version: 0.9.25 Pid: 20542
